/home/xlx9645/miniconda3/envs/maze/lib/python3.9/site-packages/gymnasium/envs/registration.py:642: UserWarning: [33mWARN: Overriding environment TrapMazeEnv already in registry.[0m
  logger.warn(f"Overriding environment {new_spec.id} already in registry.")
wandb: Using wandb-core as the SDK backend.  Please refer to https://wandb.me/wandb-core for more information.
wandb: Currently logged in as: yuxuanli2023 (yuxuanli2023-northwestern-university). Use `wandb login --relogin` to force relogin
wandb: Tracking run with wandb version 0.19.1
wandb: Run data is saved locally in /home/xlx9645/failed/Maze/update_baselines/wandb/run-20241229_185031-cw3e6jl8
wandb: Run `wandb offline` to turn off syncing.
wandb: Syncing run AIRL_on
wandb: ‚≠êÔ∏è View project at https://wandb.ai/yuxuanli2023-northwestern-university/Main_1229
wandb: üöÄ View run at https://wandb.ai/yuxuanli2023-northwestern-university/Main_1229/runs/cw3e6jl8
/home/xlx9645/miniconda3/envs/maze/lib/python3.9/site-packages/gymnasium/spaces/box.py:235: UserWarning: [33mWARN: Box low's precision lowered by casting to float32, current low.dtype=float64[0m
  gym.logger.warn(
/home/xlx9645/miniconda3/envs/maze/lib/python3.9/site-packages/gymnasium/spaces/box.py:305: UserWarning: [33mWARN: Box high's precision lowered by casting to float32, current high.dtype=float64[0m
  gym.logger.warn(
Traceback (most recent call last):
  File "/home/xlx9645/failed/Maze/update_baselines/Main_AIRL2.py", line 210, in <module>
    pseudo_reward = compute_gail_reward(state_tensor, action_tensor)
  File "/home/xlx9645/failed/Maze/update_baselines/Main_AIRL2.py", line 47, in compute_gail_reward
    logits = discriminator(state, action)
  File "/home/xlx9645/miniconda3/envs/maze/lib/python3.9/site-packages/torch/nn/modules/module.py", line 1736, in _wrapped_call_impl
    return self._call_impl(*args, **kwargs)
  File "/home/xlx9645/miniconda3/envs/maze/lib/python3.9/site-packages/torch/nn/modules/module.py", line 1747, in _call_impl
    return forward_call(*args, **kwargs)
  File "/home/xlx9645/failed/Maze/update_baselines/Main_AIRL2.py", line 71, in forward
    return self.net(x)
  File "/home/xlx9645/miniconda3/envs/maze/lib/python3.9/site-packages/torch/nn/modules/module.py", line 1736, in _wrapped_call_impl
    return self._call_impl(*args, **kwargs)
  File "/home/xlx9645/miniconda3/envs/maze/lib/python3.9/site-packages/torch/nn/modules/module.py", line 1747, in _call_impl
    return forward_call(*args, **kwargs)
  File "/home/xlx9645/miniconda3/envs/maze/lib/python3.9/site-packages/torch/nn/modules/container.py", line 250, in forward
    input = module(input)
  File "/home/xlx9645/miniconda3/envs/maze/lib/python3.9/site-packages/torch/nn/modules/module.py", line 1736, in _wrapped_call_impl
    return self._call_impl(*args, **kwargs)
  File "/home/xlx9645/miniconda3/envs/maze/lib/python3.9/site-packages/torch/nn/modules/module.py", line 1747, in _call_impl
    return forward_call(*args, **kwargs)
  File "/home/xlx9645/miniconda3/envs/maze/lib/python3.9/site-packages/torch/nn/modules/activation.py", line 133, in forward
    return F.relu(input, inplace=self.inplace)
  File "/home/xlx9645/miniconda3/envs/maze/lib/python3.9/site-packages/torch/nn/functional.py", line 1704, in relu
    result = torch.relu(input)
RuntimeError: CUDA error: out of memory
CUDA kernel errors might be asynchronously reported at some other API call, so the stacktrace below might be incorrect.
For debugging consider passing CUDA_LAUNCH_BLOCKING=1
Compile with `TORCH_USE_CUDA_DSA` to enable device-side assertions.

[1;34mwandb[0m: üöÄ View run [33mAIRL_on[0m at: [34mhttps://wandb.ai/yuxuanli2023-northwestern-university/Main_1229/runs/cw3e6jl8[0m
[1;34mwandb[0m: Find logs at: [1;35mwandb/run-20241229_185031-cw3e6jl8/logs[0m
